
libgomp: Invalid value for environment variable OMP_NUM_THREADS

libgomp: Invalid value for environment variable OMP_NUM_THREADS

libgomp: Invalid value for environment variable OMP_NUM_THREADS
Traceback (most recent call last):
  File "train.py", line 19, in <module>
    import lavis.tasks as tasks
  File "/home/atuin/g102ea/g102ea22/mr-Audio/lavis/__init__.py", line 15, in <module>
    from lavis.datasets.builders import *
  File "/home/atuin/g102ea/g102ea22/mr-Audio/lavis/datasets/builders/__init__.py", line 8, in <module>
    from lavis.datasets.builders.base_dataset_builder import load_dataset_config
  File "/home/atuin/g102ea/g102ea22/mr-Audio/lavis/datasets/builders/base_dataset_builder.py", line 17, in <module>
    from lavis.datasets.data_utils import extract_archive
  File "/home/atuin/g102ea/g102ea22/mr-Audio/lavis/datasets/data_utils.py", line 20, in <module>
    import torchaudio
  File "/home/atuin/g102ea/g102ea22/software/private/conda/envs/mrBlip/lib/python3.8/site-packages/torchaudio/__init__.py", line 2, in <module>
    from . import _extension  # noqa  # usort: skip
  File "/home/atuin/g102ea/g102ea22/software/private/conda/envs/mrBlip/lib/python3.8/site-packages/torchaudio/_extension/__init__.py", line 38, in <module>
    _load_lib("libtorchaudio")
  File "/home/atuin/g102ea/g102ea22/software/private/conda/envs/mrBlip/lib/python3.8/site-packages/torchaudio/_extension/utils.py", line 60, in _load_lib
    torch.ops.load_library(path)
  File "/home/atuin/g102ea/g102ea22/software/private/conda/envs/mrBlip/lib/python3.8/site-packages/torch/_ops.py", line 1295, in load_library
    ctypes.CDLL(path)
  File "/home/atuin/g102ea/g102ea22/software/private/conda/envs/mrBlip/lib/python3.8/ctypes/__init__.py", line 373, in __init__
    self._handle = _dlopen(self._name, mode)
OSError: libcudart.so.11.0: cannot open shared object file: No such file or directory
Traceback (most recent call last):
  File "train.py", line 19, in <module>
    import lavis.tasks as tasks
  File "/home/atuin/g102ea/g102ea22/mr-Audio/lavis/__init__.py", line 15, in <module>
    from lavis.datasets.builders import *
  File "/home/atuin/g102ea/g102ea22/mr-Audio/lavis/datasets/builders/__init__.py", line 8, in <module>
    from lavis.datasets.builders.base_dataset_builder import load_dataset_config
  File "/home/atuin/g102ea/g102ea22/mr-Audio/lavis/datasets/builders/base_dataset_builder.py", line 17, in <module>
    from lavis.datasets.data_utils import extract_archive
  File "/home/atuin/g102ea/g102ea22/mr-Audio/lavis/datasets/data_utils.py", line 20, in <module>
    import torchaudio
  File "/home/atuin/g102ea/g102ea22/software/private/conda/envs/mrBlip/lib/python3.8/site-packages/torchaudio/__init__.py", line 2, in <module>
    from . import _extension  # noqa  # usort: skip
  File "/home/atuin/g102ea/g102ea22/software/private/conda/envs/mrBlip/lib/python3.8/site-packages/torchaudio/_extension/__init__.py", line 38, in <module>
    _load_lib("libtorchaudio")
  File "/home/atuin/g102ea/g102ea22/software/private/conda/envs/mrBlip/lib/python3.8/site-packages/torchaudio/_extension/utils.py", line 60, in _load_lib
    torch.ops.load_library(path)
  File "/home/atuin/g102ea/g102ea22/software/private/conda/envs/mrBlip/lib/python3.8/site-packages/torch/_ops.py", line 1295, in load_library
    ctypes.CDLL(path)
  File "/home/atuin/g102ea/g102ea22/software/private/conda/envs/mrBlip/lib/python3.8/ctypes/__init__.py", line 373, in __init__
    self._handle = _dlopen(self._name, mode)
OSError: libcudart.so.11.0: cannot open shared object file: No such file or directory
W1215 12:30:33.299503 22536471905792 torch/distributed/elastic/multiprocessing/api.py:858] Sending process 1794670 closing signal SIGTERM
E1215 12:30:33.363733 22536471905792 torch/distributed/elastic/multiprocessing/api.py:833] failed (exitcode: 1) local_rank: 0 (pid: 1794669) of binary: /home/atuin/g102ea/g102ea22/software/private/conda/envs/mrBlip/bin/python
Traceback (most recent call last):
  File "/home/atuin/g102ea/g102ea22/software/private/conda/envs/mrBlip/lib/python3.8/runpy.py", line 194, in _run_module_as_main
    return _run_code(code, main_globals, None,
  File "/home/atuin/g102ea/g102ea22/software/private/conda/envs/mrBlip/lib/python3.8/runpy.py", line 87, in _run_code
    exec(code, run_globals)
  File "/home/atuin/g102ea/g102ea22/software/private/conda/envs/mrBlip/lib/python3.8/site-packages/torch/distributed/run.py", line 905, in <module>
    main()
  File "/home/atuin/g102ea/g102ea22/software/private/conda/envs/mrBlip/lib/python3.8/site-packages/torch/distributed/elastic/multiprocessing/errors/__init__.py", line 348, in wrapper
    return f(*args, **kwargs)
  File "/home/atuin/g102ea/g102ea22/software/private/conda/envs/mrBlip/lib/python3.8/site-packages/torch/distributed/run.py", line 901, in main
    run(args)
  File "/home/atuin/g102ea/g102ea22/software/private/conda/envs/mrBlip/lib/python3.8/site-packages/torch/distributed/run.py", line 892, in run
    elastic_launch(
  File "/home/atuin/g102ea/g102ea22/software/private/conda/envs/mrBlip/lib/python3.8/site-packages/torch/distributed/launcher/api.py", line 133, in __call__
    return launch_agent(self._config, self._entrypoint, list(args))
  File "/home/atuin/g102ea/g102ea22/software/private/conda/envs/mrBlip/lib/python3.8/site-packages/torch/distributed/launcher/api.py", line 264, in launch_agent
    raise ChildFailedError(
torch.distributed.elastic.multiprocessing.errors.ChildFailedError: 
============================================================
train.py FAILED
------------------------------------------------------------
Failures:
  <NO_OTHER_FAILURES>
------------------------------------------------------------
Root Cause (first observed failure):
[0]:
  time      : 2024-12-15_12:30:33
  host      : a0905.nhr.fau.de
  rank      : 0 (local_rank: 0)
  exitcode  : 1 (pid: 1794669)
  error_file: <N/A>
  traceback : To enable traceback see: https://pytorch.org/docs/stable/elastic/errors.html
============================================================
